Workbook

Sheet 📖 Process Guide
B1: 📖 BUGABOO LANDSCAPING LTD — CONSTRUCTION PROCESS GUIDE (SOP)
B3: 🟢 PHASE 1: ONBOARDING
B4: 1 | C4: Send pre-construction consult email to prospect | D4: Use email template to gather: scope, budget range, timeline, site photos
B5: 2 | C5: Enter client details in system & assign Operator (OO) | D5: Dashboard sheet → Project Status = 'Lead'
B6: 3 | C6: Schedule initial consultation meeting | D6: All divisions (irrigation, treecare) should coordinate if multi-scope
B8: 🟡 PHASE 2: QUOTING & DESIGN
B9: 4 | C9: OO meets client — capture vision, take measurements | D9: Bring measuring tape, camera, site sketch pad
B10: 5 | C10: Complete TAKEOFF SHEET (📊 Takeoff & Quote tab) | D10: Fill in all quantities, material costs, labour & machine hours, mobilization
B11: 6 | C11: Review quote internally before sending | D11: Check: margin ≥ 35%, all sections filled, notes added
B12: 7 | C12: Generate Customer Quote (📄 Customer Quote tab) | D12: Transfer line items; review for client-friendly language
B13: 8 | C13: Send quote — follow up within 3 business days | D13: Update Dashboard → Status = 'Quoted'
B14: 9 | C14: Obtain signed acceptance + 50% deposit | D14: Update Dashboard → Status = 'Deposit Received'
B16: 🔵 PHASE 3: PRE-CONSTRUCTION (1–4 weeks)
B17: 10 | C17: Apply for permits; order locates | D17: Update Dashboard timeline — Est. Start date for each phase
B18: 11 | C18: Order materials with lead-time in mind | D18: Log in 🧾 Material Log tab — match to takeoff budget
B19: 12 | C19: Confirm OO schedule and project start date | D19: Notify client of start date + any factors that may affect timeline
B21: 🟠 PHASE 4: CONSTRUCTION
B22: 13 | C22: Demolition (1–2 days) | D22: Log labour hours daily in ⏱️ Labour & Machine Log
B23: 14 | C23: Grading & Drainage (1–2 days) | D23: Record dump loads, fuel costs in Material Log (category: Mobilization)
B24: 15 | C24: Irrigation install (1–2 days) | D24: Cross-check against takeoff hours — flag overages immediately
B25: 16 | C25: Hardscape install (variable) | D25: Photo-document each phase for warranty & customer completion package
B26: 17 | C26: Planting / Sod (1–2 days) | D26: Confirm soil, sod, plant quantities match material log
B27: 18 | C27: Final touches / cleanup (1–2 days) | D27: Site photos — before and after required
B29: 🔴 PHASE 5: PROJECT COMPLETION
B30: 19 | C30: Final walkthrough with client — punchlist | D30: Address all issues before final invoice
B31: 20 | C31: Prepare completion package | D31: Before/after photos, watering instructions, warranty document, care guide
B32: 21 | C32: Send final invoice (remaining 50%) | D32: Update Dashboard → Status = 'Punch List' → 'Complete'
B33: 22 | C33: Collect Google/Facebook review | D33: Send review link immediately after completion call
B35: 🟣 PHASE 6: RECONCILIATION
B36: 23 | C36: Reconcile all material receipts vs. takeoff budget | D36: 🧾 Material Log — ensure every receipt is logged
B37: 24 | C37: Reconcile all labour & machine hours vs. estimate | D37: ⏱️ Labour & Machine Log — total vs. takeoff hours
B38: 25 | C38: Complete Project P&L (🔄 Reconcile P&L tab) | D38: Enter actual invoiced revenue; review variances
B39: 26 | C39: Document lessons learned | D39: Note: any items consistently over/under budget for future estimating accuracy
B40: 27 | C40: Archive project & close in system | D40: Change Dashboard → Status = 'Complete'

Sheet 📋 Dashboard
B1: 🌿 BUGABOO LANDSCAPING LTD — PROJECT MANAGEMENT SYSTEM
B3: Project Name: | F3: FINANCIAL SUMMARY
B4: Project Address: | F4: Quote / Contract Value | H4: ='📊 Takeoff & Quote'!Q7 -> 0
B5: Client Name: | F5: Total Est. Direct Cost | H5: ='📊 Takeoff & Quote'!Q8 -> 0
B6: Client Phone: | F6: Gross Profit $ | H6: ='📊 Takeoff & Quote'!Q9 -> 0
B7: Client Email: | F7: Gross Margin % | H7: ='📊 Takeoff & Quote'!Q10 -> 0
B8: Operator (OO):
B9: OO Phone: | F9: ACTUAL (Reconciled)
B10: Project Start: | F10: Actual Revenue | H10: ='🔄 Reconcile P&L'!G5 -> 0
B11: Est. Completion: | F11: Actual Total Cost | H11: ='🔄 Reconcile P&L'!G6 -> 0
B12: Project Status: | F12: Actual Gross Profit | H12: ='🔄 Reconcile P&L'!G7 -> 0
F13: Actual Margin % | H13: ='🔄 Reconcile P&L'!G8 -> 0
B14: PROJECT TIMELINE & MILESTONES
B15: Phase | C15: Description | D15: Est. Start | E15: Est. End | F15: Actual Start | G15: Actual End | H15: Status
B16: Permitting / Locates
B17: Demolition
B18: Grading & Drainage
B19: Irrigation
B20: Hardscape
B21: Planting
B22: Final Touches / Cleanup
B23: PROJECT NOTES & COMMUNICATION LOG
B24: Note 1:
B25: Note 2:
B26: Note 3:
B27: Note 4:
... B29: Note 6:

Sheet 📊 Takeoff & Quote
B1: 🌿 BUGABOO LANDSCAPING LTD — PROJECT TAKEOFF & QUOTE
B2: Client Name: | G2: Project Name:
B3: Address: | G3: Operator (OO):
B4: Phone: | G4: Quote Date:
B5: Email: | G5: Quote #:
B6: Project Description:
B7: PRICING ASSUMPTIONS | Blue = Input | E8 = Internal Labour Cost ($30) | P8 = Client Bill Rate ($90 - trucks/trailers/WCB/insurance/overhead) | Q7: =Q66 -> 0 | R7: =Q66 -> 0
B8: Material Markup % | C8: 0.25 | D8: Internal Labour ($/hr) | E8: 30 | F8: Machine Rate ($/hr) | G8: 145 | H8: Fuel Cost/Load | I8: 45 | J8: Dump Fee/Load | K8: 120 | L8: Delivery Fee | M8: 150 | N8: Desired Margin % | O8: 0.35 | Q8: =Q65 -> 0 | R8: =Q65 -> 0
B9: # | C9: Scope / Line Item | D9: Unit | E9: Qty | F9: Material Cost/Unit | G9: Total Material | H9: Labour Hours | I9: Labour Cost (Internal) | J9: Machine Hours | K9: Machine Cost | L9: Mobiliz. & Other | M9: LINE TOTAL (Cost) | N9: Markup Added | O9: Quoted Line Price | P9: Notes | Q9: =Q7-Q8 -> 0 | R9: =Q69 -> 0
B10: 🔨 DEMOLITION & REMOVAL | Q10: =IF(Q7=0,0,Q9/Q7) -> 0 | R10: =Q70 -> 0
B11: 1 | C11: Remove & dispose existing soil | G11: =IF(E11="","-",E11*F11) -> - | I11: =IF(H11="","-",H11*$E$8) -> - | K11: =IF(J11="","-",J11*$G$8) -> - | M11: =IFERROR(IF(G11="-",0,G11)+IF(I11="-",0,I11)+IF(K11="-",0,K11)+IF(L11="",0,L11),0) -> 0 | N11: =IFERROR((IF(G11="-",0,G11)*$C$8),0) -> 0 | O11: =IFERROR((IF(G11="-",0,G11)*(1+$C$8)) + (IF(H11="",0,H11)*$P$8) + IF(K11="-",0,K11) + IF(L11="",0,L11),0) -> 0
B12: 2 | C12: Remove & dispose boulders / rocks | G12: =IF(E12="","-",E12*F12) -> - | I12: =IF(H12="","-",H12*$E$8) -> - | K12: =IF(J12="","-",J12*$G$8) -> - | M12: =IFERROR(IF(G12="-",0,G12)+IF(I12="-",0,I12)+IF(K12="-",0,K12)+IF(L12="",0,L12),0) -> 0 | N12: =IFERROR((IF(G12="-",0,G12)*$C$8),0) -> 0 | O12: =IFERROR((IF(G12="-",0,G12)*(1+$C$8)) + (IF(H12="",0,H12)*$P$8) + IF(K12="-",0,K12) + IF(L12="",0,L12),0) -> 0
B13: 3 | C13: Remove existing hardscape | G13: =IF(E13="","-",E13*F13) -> - | I13: =IF(H13="","-",H13*$E$8) -> - | K13: =IF(J13="","-",J13*$G$8) -> - | M13: =IFERROR(IF(G13="-",0,G13)+IF(I13="-",0,I13)+IF(K13="-",0,K13)+IF(L13="",0,L13),0) -> 0 | N13: =IFERROR((IF(G13="-",0,G13)*$C$8),0) -> 0 | O13: =IFERROR((IF(G13="-",0,G13)*(1+$C$8)) + (IF(H13="",0,H13)*$P$8) + IF(K13="-",0,K13) + IF(L13="",0,L13),0) -> 0
B14: 4 | C14: Haul-away / dump loads | G14: =IF(E14="","-",E14*F14) -> - | I14: =IF(H14="","-",H14*$E$8) -> - | K14: =IF(J14="","-",J14*$G$8) -> - | M14: =IFERROR(IF(G14="-",0,G14)+IF(I14="-",0,I14)+IF(K14="-",0,K14)+IF(L14="",0,L14),0) -> 0 | N14: =IFERROR((IF(G14="-",0,G14)*$C$8),0) -> 0 | O14: =IFERROR((IF(G14="-",0,G14)*(1+$C$8)) + (IF(H14="",0,H14)*$P$8) + IF(K14="-",0,K14) + IF(L14="",0,L14),0) -> 0
B15: Subtotal — 🔨 DEMOLITION & REMOVAL | M15: =SUM(M11:M14) -> 0 | O15: =SUM(O11:O14) -> 0
B17: 🏔️ GRADING & DRAINAGE
B18: 1 | C18: Spread, grade & compact | G18: =IF(E18="","-",E18*F18) -> - | I18: =IF(H18="","-",H18*$E$8) -> - | K18: =IF(J18="","-",J18*$G$8) -> - | M18: =IFERROR(IF(G18="-",0,G18)+IF(I18="-",0,I18)+IF(K18="-",0,K18)+IF(L18="",0,L18),0) -> 0 | N18: =IFERROR((IF(G18="-",0,G18)*$C$8),0) -> 0 | O18: =IFERROR((IF(G18="-",0,G18)*(1+$C$8)) + (IF(H18="",0,H18)*$P$8) + IF(K18="-",0,K18) + IF(L18="",0,L18),0) -> 0
B19: 2 | C19: Fine grading | G19: =IF(E19="","-",E19*F19) -> - | I19: =IF(H19="","-",H19*$E$8) -> - | K19: =IF(J19="","-",J19*$G$8) -> - | M19: =IFERROR(IF(G19="-",0,G19)+IF(I19="-",0,I19)+IF(K19="-",0,K19)+IF(L19="",0,L19),0) -> 0 | N19: =IFERROR((IF(G19="-",0,G19)*$C$8),0) -> 0 | O19: =IFERROR((IF(G19="-",0,G19)*(1+$C$8)) + (IF(H19="",0,H19)*$P$8) + IF(K19="-",0,K19) + IF(L19="",0,L19),0) -> 0
B20: 3 | C20: Drainage swale / French drain | G20: =IF(E20="","-",E20*F20) -> - | I20: =IF(H20="","-",H20*$E$8) -> - | K20: =IF(J20="","-",J20*$G$8) -> - | M20: =IFERROR(IF(G20="-",0,G20)+IF(I20="-",0,I20)+IF(K20="-",0,K20)+IF(L20="",0,L20),0) -> 0 | N20: =IFERROR((IF(G20="-",0,G20)*$C$8),0) -> 0 | O20: =IFERROR((IF(G20="-",0,G20)*(1+$C$8)) + (IF(H20="",0,H20)*$P$8) + IF(K20="-",0,K20) + IF(L20="",0,L20),0) -> 0
B21: 4 | C21: Topsoil supply & spread | G21: =IF(E21="","-",E21*F21) -> - | I21: =IF(H21="","-",H21*$E$8) -> - | K21: =IF(J21="","-",J21*$G$8) -> - | M21: =IFERROR(IF(G21="-",0,G21)+IF(I21="-",0,I21)+IF(K21="-",0,K21)+IF(L21="",0,L21),0) -> 0 | N21: =IFERROR((IF(G21="-",0,G21)*$C$8),0) -> 0 | O21: =IFERROR((IF(G21="-",0,G21)*(1+$C$8)) + (IF(H21="",0,H21)*$P$8) + IF(K21="-",0,K21) + IF(L21="",0,L21),0) -> 0
B22: Subtotal — 🏔️ GRADING & DRAINAGE | M22: =SUM(M18:M21) -> 0 | O22: =SUM(O18:O21) -> 0
B24: 💧 IRRIGATION
B25: 1 | C25: Irrigation design & permits | G25: =IF(E25="","-",E25*F25) -> - | I25: =IF(H25="","-",H25*$E$8) -> - | K25: =IF(J25="","-",J25*$G$8) -> - | M25: =IFERROR(IF(G25="-",0,G25)+IF(I25="-",0,I25)+IF(K25="-",0,K25)+IF(L25="",0,L25),0) -> 0 | N25: =IFERROR((IF(G25="-",0,G25)*$C$8),0) -> 0 | O25: =IFERROR((IF(G25="-",0,G25)*(1+$C$8)) + (IF(H25="",0,H25)*$P$8) + IF(K25="-",0,K25) + IF(L25="",0,L25),0) -> 0
B26: 2 | C26: Main line & lateral trenching | G26: =IF(E26="","-",E26*F26) -> - | I26: =IF(H26="","-",H26*$E$8) -> - | K26: =IF(J26="","-",J26*$G$8) -> - | M26: =IFERROR(IF(G26="-",0,G26)+IF(I26="-",0,I26)+IF(K26="-",0,K26)+IF(L26="",0,L26),0) -> 0 | N26: =IFERROR((IF(G26="-",0,G26)*$C$8),0) -> 0 | O26: =IFERROR((IF(G26="-",0,G26)*(1+$C$8)) + (IF(H26="",0,H26)*$P$8) + IF(K26="-",0,K26) + IF(L26="",0,L26),0) -> 0
B27: 3 | C27: Heads, valves & controller | G27: =IF(E27="","-",E27*F27) -> - | I27: =IF(H27="","-",H27*$E$8) -> - | K27: =IF(J27="","-",J27*$G$8) -> - | M27: =IFERROR(IF(G27="-",0,G27)+IF(I27="-",0,I27)+IF(K27="-",0,K27)+IF(L27="",0,L27),0) -> 0 | N27: =IFERROR((IF(G27="-",0,G27)*$C$8),0) -> 0 | O27: =IFERROR((IF(G27="-",0,G27)*(1+$C$8)) + (IF(H27="",0,H27)*$P$8) + IF(K27="-",0,K27) + IF(L27="",0,L27),0) -> 0
B28: 4 | C28: Startup & testing | G28: =IF(E28="","-",E28*F28) -> - | I28: =IF(H28="","-",H28*$E$8) -> - | K28: =IF(J28="","-",J28*$G$8) -> - | M28: =IFERROR(IF(G28="-",0,G28)+IF(I28="-",0,I28)+IF(K28="-",0,K28)+IF(L28="",0,L28),0) -> 0 | N28: =IFERROR((IF(G28="-",0,G28)*$C$8),0) -> 0 | O28: =IFERROR((IF(G28="-",0,G28)*(1+$C$8)) + (IF(H28="",0,H28)*$P$8) + IF(K28="-",0,K28) + IF(L28="",0,L28),0) -> 0
B29: Subtotal — 💧 IRRIGATION | M29: =SUM(M25:M28) -> 0 | O29: =SUM(O25:O28) -> 0
B31: 🧱 HARDSCAPE
B32: 1 | C32: Patio – excavation & base | G32: =IF(E32="","-",E32*F32) -> - | I32: =IF(H32="","-",H32*$E$8) -> - | K32: =IF(J32="","-",J32*$G$8) -> - | M32: =IFERROR(IF(G32="-",0,G32)+IF(I32="-",0,I32)+IF(K32="-",0,K32)+IF(L32="",0,L32),0) -> 0 | N32: =IFERROR((IF(G32="-",0,G32)*$C$8),0) -> 0 | O32: =IFERROR((IF(G32="-",0,G32)*(1+$C$8)) + (IF(H32="",0,H32)*$P$8) + IF(K32="-",0,K32) + IF(L32="",0,L32),0) -> 0
B33: 2 | C33: Patio – stone / pavers supply & lay | G33: =IF(E33="","-",E33*F33) -> - | I33: =IF(H33="","-",H33*$E$8) -> - | K33: =IF(J33="","-",J33*$G$8) -> - | M33: =IFERROR(IF(G33="-",0,G33)+IF(I33="-",0,I33)+IF(K33="-",0,K33)+IF(L33="",0,L33),0) -> 0 | N33: =IFERROR((IF(G33="-",0,G33)*$C$8),0) -> 0 | O33: =IFERROR((IF(G33="-",0,G33)*(1+$C$8)) + (IF(H33="",0,H33)*$P$8) + IF(K33="-",0,K33) + IF(L33="",0,L33),0) -> 0
B34: 3 | C34: Retaining wall – excavation & base | G34: =IF(E34="","-",E34*F34) -> - | I34: =IF(H34="","-",H34*$E$8) -> - | K34: =IF(J34="","-",J34*$G$8) -> - | M34: =IFERROR(IF(G34="-",0,G34)+IF(I34="-",0,I34)+IF(K34="-",0,K34)+IF(L34="",0,L34),0) -> 0 | N34: =IFERROR((IF(G34="-",0,G34)*$C$8),0) -> 0 | O34: =IFERROR((IF(G34="-",0,G34)*(1+$C$8)) + (IF(H34="",0,H34)*$P$8) + IF(K34="-",0,K34) + IF(L34="",0,L34),0) -> 0
B35: 4 | C35: Retaining wall – block supply & build | G35: =IF(E35="","-",E35*F35) -> - | I35: =IF(H35="","-",H35*$E$8) -> - | K35: =IF(J35="","-",J35*$G$8) -> - | M35: =IFERROR(IF(G35="-",0,G35)+IF(I35="-",0,I35)+IF(K35="-",0,K35)+IF(L35="",0,L35),0) -> 0 | N35: =IFERROR((IF(G35="-",0,G35)*$C$8),0) -> 0 | O35: =IFERROR((IF(G35="-",0,G35)*(1+$C$8)) + (IF(H35="",0,H35)*$P$8) + IF(K35="-",0,K35) + IF(L35="",0,L35),0) -> 0
B36: 5 | C36: Walkway / steps | G36: =IF(E36="","-",E36*F36) -> - | I36: =IF(H36="","-",H36*$E$8) -> - | K36: =IF(J36="","-",J36*$G$8) -> - | M36: =IFERROR(IF(G36="-",0,G36)+IF(I36="-",0,I36)+IF(K36="-",0,K36)+IF(L36="",0,L36),0) -> 0 | N36: =IFERROR((IF(G36="-",0,G36)*$C$8),0) -> 0 | O36: =IFERROR((IF(G36="-",0,G36)*(1+$C$8)) + (IF(H36="",0,H36)*$P$8) + IF(K36="-",0,K36) + IF(L36="",0,L36),0) -> 0
B37: 6 | C37: Edging | G37: =IF(E37="","-",E37*F37) -> - | I37: =IF(H37="","-",H37*$E$8) -> - | K37: =IF(J37="","-",J37*$G$8) -> - | M37: =IFERROR(IF(G37="-",0,G37)+IF(I37="-",0,I37)+IF(K37="-",0,K37)+IF(L37="",0,L37),0) -> 0 | N37: =IFERROR((IF(G37="-",0,G37)*$C$8),0) -> 0 | O37: =IFERROR((IF(G37="-",0,G37)*(1+$C$8)) + (IF(H37="",0,H37)*$P$8) + IF(K37="-",0,K37) + IF(L37="",0,L37),0) -> 0
B38: Subtotal — 🧱 HARDSCAPE | M38: =SUM(M32:M37) -> 0 | O38: =SUM(O32:O37) -> 0
B40: 🌱 SOFTSCAPE & PLANTING
B41: 1 | C41: Sod – supply & install | G41: =IF(E41="","-",E41*F41) -> - | I41: =IF(H41="","-",H41*$E$8) -> - | K41: =IF(J41="","-",J41*$G$8) -> - | M41: =IFERROR(IF(G41="-",0,G41)+IF(I41="-",0,I41)+IF(K41="-",0,K41)+IF(L41="",0,L41),0) -> 0 | N41: =IFERROR((IF(G41="-",0,G41)*$C$8),0) -> 0 | O41: =IFERROR((IF(G41="-",0,G41)*(1+$C$8)) + (IF(H41="",0,H41)*$P$8) + IF(K41="-",0,K41) + IF(L41="",0,L41),0) -> 0
B42: 2 | C42: Loam / premium soil supply | G42: =IF(E42="","-",E42*F42) -> - | I42: =IF(H42="","-",H42*$E$8) -> - | K42: =IF(J42="","-",J42*$G$8) -> - | M42: =IFERROR(IF(G42="-",0,G42)+IF(I42="-",0,I42)+IF(K42="-",0,K42)+IF(L42="",0,L42),0) -> 0 | N42: =IFERROR((IF(G42="-",0,G42)*$C$8),0) -> 0 | O42: =IFERROR((IF(G42="-",0,G42)*(1+$C$8)) + (IF(H42="",0,H42)*$P$8) + IF(K42="-",0,K42) + IF(L42="",0,L42),0) -> 0
B43: 3 | C43: Shrubs & perennials – supply & plant | G43: =IF(E43="","-",E43*F43) -> - | I43: =IF(H43="","-",H43*$E$8) -> - | K43: =IF(J43="","-",J43*$G$8) -> - | M43: =IFERROR(IF(G43="-",0,G43)+IF(I43="-",0,I43)+IF(K43="-",0,K43)+IF(L43="",0,L43),0) -> 0 | N43: =IFERROR((IF(G43="-",0,G43)*$C$8),0) -> 0 | O43: =IFERROR((IF(G43="-",0,G43)*(1+$C$8)) + (IF(H43="",0,H43)*$P$8) + IF(K43="-",0,K43) + IF(L43="",0,L43),0) -> 0
B44: 4 | C44: Landscape fabric supply & install (weed suppression) | G44: =IF(E44="","-",E44*F44) -> - | I44: =IF(H44="","-",H44*$E$8) -> - | K44: =IF(J44="","-",J44*$G$8) -> - | M44: =IFERROR(IF(G44="-",0,G44)+IF(I44="-",0,I44)+IF(K44="-",0,K44)+IF(L44="",0,L44),0) -> 0 | N44: =IFERROR((IF(G44="-",0,G44)*$C$8),0) -> 0 | O44: =IFERROR((IF(G44="-",0,G44)*(1+$C$8)) + (IF(H44="",0,H44)*$P$8) + IF(K44="-",0,K44) + IF(L44="",0,L44),0) -> 0
...

Sheet 📄 Customer Quote
B1: BUGABOO LANDSCAPING LTD
B2: 📞 403-283-7843 | ✉️ Support@bugaboolandscaping.com | 🌐 www.bugaboolandscaping.com
B4: PREPARED FOR: | D4: QUOTE DETAILS
B5: Client Name: | C5: ='📊 Takeoff & Quote'!C2 -> 0 | D5: Quote #: | E5: ='📊 Takeoff & Quote'!H5 -> 0
B6: Address: | C6: ='📊 Takeoff & Quote'!C3 -> 0 | D6: Date: | E6: ='📊 Takeoff & Quote'!H4 -> 0
B7: Phone: | C7: ='📊 Takeoff & Quote'!C4 -> 0 | D7: Valid Until:
B8: Email: | C8: ='📊 Takeoff & Quote'!C5 -> 0 | D8: Operator: | E8: ='📊 Takeoff & Quote'!H3 -> 0
B9: PROJECT DESCRIPTION
B10: ='📊 Takeoff & Quote'!C6 -> 0
B11: SCOPE OF WORK | C11: UNIT | D11: QTY | E11: PRICE
B34: Subtotal | E34: =SUM(E12:E32) -> 0
B35: GST (5%) | E35: =E34*0.05 -> 0
B36: TOTAL | E36: =E34+E35 -> 0
B38: ⚠️ A 50% deposit is required to secure your project start date.
B39: Note: This estimate is valid for 30 days. Final costs may vary due to unforeseen site conditions.
B41: WARRANTY SUMMARY
B42: ✔ General Workmanship: 2 years
B43: ✔ Stone Patios & Retaining Walls: 2 years against major shifting/settling
B44: ✔ Woodwork (decks, fences, pergolas): 2 years structural defects
B45: ✔ Irrigation: 2 years parts & labor (proper winterization required)
B46: ✗ Plants, sod, shrubs, trees: No warranty (living material – proper aftercare required)
B48: ACCEPTANCE & AUTHORIZATION
B49: I/We hereby accept this proposal and authorize Bugaboo Landscaping Ltd to proceed.
B50: Client Signature: ___________________________ | D50: Date: _______________
B51: Print Name: ___________________________

Sheet 🧾 Material Log
B1: 🧾 MATERIAL PURCHASE LOG — Track Every Receipt Against Budget
B2: Date | C2: Supplier / Vendor | D2: Description / Item | E2: Category | F2: Qty | G2: Unit Cost | H2: Total Cost | I2: Budget (Takeoff) | J2: Over/Under | K2: Invoice # | L2: Notes
G3: =IF(F3="","-",F3*G3) -> - | I3: =IF(OR(H3=0,H3=""),"-",H3-G3) -> -
G4: =IF(F4="","-",F4*G4) -> - | I4: =IF(OR(H4=0,H4=""),"-",H4-G4) -> -
G5: =IF(F5="","-",F5*G5) -> - | I5: =IF(OR(H5=0,H5=""),"-",H5-G5) -> -
G6: =IF(F6="","-",F6*G6) -> - | I6: =IF(OR(H6=0,H6=""),"-",H6-G6) -> -
G7: =IF(F7="","-",F7*G7) -> - | I7: =IF(OR(H7=0,H7=""),"-",H7-G7) -> -
G8: =IF(F8="","-",F8*G8) -> - | I8: =IF(OR(H8=0,H8=""),"-",H8-G8) -> -
G9: =IF(F9="","-",F9*G9) -> - | I9: =IF(OR(H9=0,H9=""),"-",H9-G9) -> -
G10: =IF(F10="","-",F10*G10) -> - | I10: =IF(OR(H10=0,H10=""),"-",H10-G10) -> -
G11: =IF(F11="","-",F11*G11) -> - | I11: =IF(OR(H11=0,H11=""),"-",H11-G11) -> -
G12: =IF(F12="","-",F12*G12) -> - | I12: =IF(OR(H12=0,H12=""),"-",H12-G12) -> -
G13: =IF(F13="","-",F13*G13) -> - | I13: =IF(OR(H13=0,H13=""),"-",H13-G13) -> -
G14: =IF(F14="","-",F14*G14) -> - | I14: =IF(OR(H14=0,H14=""),"-",H14-G14) -> -
... G32: =IF(F32="","-",F32*G32) -> - | I32: =IF(OR(H32=0,H32=""),"-",H32-G32) -> -
B33: TOTAL MATERIAL SPEND | G33: =SUMIF(H3:H32,">0",H3:H32) -> 0

Sheet ⏱️ Labour & Machine Log
B1: ⏱️ LABOUR & MACHINE TIME LOG — Track Hours vs. Budget
B2: Date | C2: Worker / Operator | D2: Task / Phase | E2: Labour Hrs | F2: Internal Rate ($/hr) | G2: Internal Labour Cost | H2: Machine Hrs | I2: Machine Rate | J2: Machine Cost | K2: Notes | L2: Labour Billed ($90/hr)
F3: 30 | G3: =IF(OR(E3="",E3=0),"-",E3*F3) -> - | I3: ='📊 Takeoff & Quote'!$G$8 -> 145 | J3: =IF(OR(H3="",H3=0),"-",H3*I3) -> - | L3: =IF(OR(E3="",E3=0),"-",E3*90) -> -
F4: 30 | G4: =IF(OR(E4="",E4=0),"-",E4*F4) -> - | I4: ='📊 Takeoff & Quote'!$G$8 -> 145 | J4: =IF(OR(H4="",H4=0),"-",H4*I4) -> - | L4: =IF(OR(E4="",E4=0),"-",E4*90) -> -
F5: 30 | G5: =IF(OR(E5="",E5=0),"-",E5*F5) -> - | I5: ='📊 Takeoff & Quote'!$G$8 -> 145 | J5: =IF(OR(H5="",H5=0),"-",H5*I5) -> - | L5: =IF(OR(E5="",E5=0),"-",E5*90) -> -
F6: 30 | G6: =IF(OR(E6="",E6=0),"-",E6*F6) -> - | I6: ='📊 Takeoff & Quote'!$G$8 -> 145 | J6: =IF(OR(H6="",H6=0),"-",H6*I6) -> - | L6: =IF(OR(E6="",E6=0),"-",E6*90) -> -
F7: 30 | G7: =IF(OR(E7="",E7=0),"-",E7*F7) -> - | I7: ='📊 Takeoff & Quote'!$G$8 -> 145 | J7: =IF(OR(H7="",H7=0),"-",H7*I7) -> - | L7: =IF(OR(E7="",E7=0),"-",E7*90) -> -
F8: 30 | G8: =IF(OR(E8="",E8=0),"-",E8*F8) -> - | I8: ='📊 Takeoff & Quote'!$G$8 -> 145 | J8: =IF(OR(H8="",H8=0),"-",H8*I8) -> - | L8: =IF(OR(E8="",E8=0),"-",E8*90) -> -
F9: 30 | G9: =IF(OR(E9="",E9=0),"-",E9*F9) -> - | I9: ='📊 Takeoff & Quote'!$G$8 -> 145 | J9: =IF(OR(H9="",H9=0),"-",H9*I9) -> - | L9: =IF(OR(E9="",E9=0),"-",E9*90) -> -
F10: 30 | G10: =IF(OR(E10="",E10=0),"-",E10*F10) -> - | I10: ='📊 Takeoff & Quote'!$G$8 -> 145 | J10: =IF(OR(H10="",H10=0),"-",H10*I10) -> - | L10: =IF(OR(E10="",E10=0),"-",E10*90) -> -
F11: 30 | G11: =IF(OR(E11="",E11=0),"-",E11*F11) -> - | I11: ='📊 Takeoff & Quote'!$G$8 -> 145 | J11: =IF(OR(H11="",H11=0),"-",H11*I11) -> - | L11: =IF(OR(E11="",E11=0),"-",E11*90) -> -
F12: 30 | G12: =IF(OR(E12="",E12=0),"-",E12*F12) -> - | I12: ='📊 Takeoff & Quote'!$G$8 -> 145 | J12: =IF(OR(H12="",H12=0),"-",H12*I12) -> - | L12: =IF(OR(E12="",E12=0),"-",E12*90) -> -
F13: 30 | G13: =IF(OR(E13="",E13=0),"-",E13*F13) -> - | I13: ='📊 Takeoff & Quote'!$G$8 -> 145 | J13: =IF(OR(H13="",H13=0),"-",H13*I13) -> - | L13: =IF(OR(E13="",E13=0),"-",E13*90) -> -
F14: 30 | G14: =IF(OR(E14="",E14=0),"-",E14*F14) -> - | I14: ='📊 Takeoff & Quote'!$G$8 -> 145 | J14: =IF(OR(H14="",H14=0),"-",H14*I14) -> - | L14: =IF(OR(E14="",E14=0),"-",E14*90) -> -
... F31: 30 | G31: =IF(OR(E31="",E31=0),"-",E31*F31) -> - | I31: ='📊 Takeoff & Quote'!$G$8 -> 145 | J31: =IF(OR(H31="",H31=0),"-",H31*I31) -> - | L31: =IF(OR(E31="",E31=0),"-",E31*90) -> -
E32: =IFERROR(SUM(E3:E31),0) -> 0 | F32: 30 | G32: =IFERROR(SUMPRODUCT((ISNUMBER(G3:G31))*(G3:G31)),0) -> 0 | H32: =IFERROR(SUM(H3:H31),0) -> 0 | I32: ='📊 Takeoff & Quote'!$G$8 -> 145 | J32: =IFERROR(SUMPRODUCT((ISNUMBER(J3:J31))*(J3:J31)),0) -> 0 | L32: =IFERROR(SUMPRODUCT((ISNUMBER(L3:L31))*(L3:L31)),0) -> 0
B33: TOTALS | D33: =SUM(D3:D32) -> 0 | F33: =SUM(F3:F32) -> 900 | G33: =SUM(G3:G32) -> 0 | I33: =SUM(I3:I32) -> 4350

Sheet 🔄 Reconcile P&L
B1: 🔄 PROJECT RECONCILIATION & PROFIT & LOSS
B2: REVENUE
B3: Line Item | C3: Quoted | D3: Actual (Invoiced) | E3: Variance $ | F3: Variance %
B4: Project Revenue (excl. GST) | C4: ='📊 Takeoff & Quote'!Q7 -> 0 | E4: =D4-C4 -> 0
B5: COST OF GOODS SOLD (DIRECT COSTS) | G5: =D4 -> 0
B6: Cost Category | C6: Quoted Cost | D6: Actual Cost | E6: Variance $ | F6: Variance % | G6: =D13 -> 0
B7: Materials | C7: =IFERROR(SUMIF('📊 Takeoff & Quote'!G11:G14,">0",'📊 Takeoff & Quote'!G11:G14)+SUMIF('📊 Takeoff & Quote'!G18:G21,">0",'📊 Takeoff & Quote'!G18:G21)+SUMIF('📊 Takeoff & Quote'!G25:G28,">0",'📊 Takeoff & Quote'!G25:G28)+SUMIF('📊 Takeoff & Quote'!G32:G37,">0",'📊 Takeoff & Quote'!G32:G37)+SUMIF('📊 Takeoff & Quote'!G41:G45,">0",'📊 Takeoff & Quote'!G41:G45)+SUMIF('📊 Takeoff & Quote'!G49:G52,">0",'📊 Takeoff & Quote'!G49:G52)+SUMIF('📊 Takeoff & Quote'!G56:G61,">0",'📊 Takeoff & Quote'!G56:G61),0) -> 0 | D7: =IFERROR(SUM('🧾 Material Log'!H3:H32),0) -> 0 | E7: =IF(C7=0,"-",D7-C7) -> - | F7: =IF(C7=0,0,(D7-C7)/C7) -> 0 | G7: =D26 -> 0
B8: Labour | C8: =IFERROR((SUMIF('📊 Takeoff & Quote'!H11:H14,">0",'📊 Takeoff & Quote'!H11:H14)+SUMIF('📊 Takeoff & Quote'!H18:H21,">0",'📊 Takeoff & Quote'!H18:H21)+SUMIF('📊 Takeoff & Quote'!H25:H28,">0",'📊 Takeoff & Quote'!H25:H28)+SUMIF('📊 Takeoff & Quote'!H32:H37,">0",'📊 Takeoff & Quote'!H32:H37)+SUMIF('📊 Takeoff & Quote'!H41:H45,">0",'📊 Takeoff & Quote'!H41:H45)+SUMIF('📊 Takeoff & Quote'!H49:H52,">0",'📊 Takeoff & Quote'!H49:H52)+SUMIF('📊 Takeoff & Quote'!H56:H61,">0",'📊 Takeoff & Quote'!H56:H61))*'📊 Takeoff & Quote'!E8,0) -> 0 | D8: =IFERROR(SUMPRODUCT((ISNUMBER('⏱️ Labour & Machine Log'!G3:G31))*('⏱️ Labour & Machine Log'!G3:G31)),0) -> 0 | E8: =IF(C8=0,"-",D8-C8) -> - | F8: =IF(C8=0,0,(D8-C8)/C8) -> 0 | G8: =D27 -> 0
B9: Equipment / Machine | C9: =IFERROR((SUMIF('📊 Takeoff & Quote'!J11:J14,">0",'📊 Takeoff & Quote'!J11:J14)+SUMIF('📊 Takeoff & Quote'!J18:J21,">0",'📊 Takeoff & Quote'!J18:J21)+SUMIF('📊 Takeoff & Quote'!J25:J28,">0",'📊 Takeoff & Quote'!J25:J28)+SUMIF('📊 Takeoff & Quote'!J32:J37,">0",'📊 Takeoff & Quote'!J32:J37)+SUMIF('📊 Takeoff & Quote'!J41:J45,">0",'📊 Takeoff & Quote'!J41:J45)+SUMIF('📊 Takeoff & Quote'!J49:J52,">0",'📊 Takeoff & Quote'!J49:J52)+SUMIF('📊 Takeoff & Quote'!J56:J61,">0",'📊 Takeoff & Quote'!J56:J61))*'📊 Takeoff & Quote'!G8,0) -> 0 | D9: =IFERROR(SUMPRODUCT((ISNUMBER('⏱️ Labour & Machine Log'!J3:J31))*('⏱️ Labour & Machine Log'!J3:J31)),0) -> 0 | E9: =IF(C9=0,"-",D9-C9) -> - | F9: =IF(C9=0,0,(D9-C9)/C9) -> 0
B10: Mobilization (Fuel, Dump, Delivery) | C10: ='📊 Takeoff & Quote'!M62 -> 0 | E10: =IF(C10=0,"-",D10-C10) -> - | F10: =IF(C10=0,0,(D10-C10)/C10) -> 0
B11: Sub-Contractors | E11: =IF(C11=0,"-",D11-C11) -> - | F11: =IF(C11=0,0,(D11-C11)/C11) -> 0
B12: Other Direct Costs | E12: =IF(C12=0,"-",D12-C12) -> - | F12: =IF(C12=0,0,(D12-C12)/C12) -> 0
B13: TOTAL DIRECT COST | C13: =SUM(C7:C12) -> 0 | D13: =SUM(D7:D12) -> 0 | E13: =D13-C13 -> 0 | F13: =IF(C13=0,0,(D13-C13)/C13) -> 0
B15: OVERHEAD & INDIRECT COSTS
B16: Category | C16: Quoted | D16: Actual | E16: Variance $ | F16: Variance %
B17: Warranty Reserve | E17: =D17-C17 -> 0 | F17: =IF(C17=0,0,(D17-C17)/C17) -> 0
B18: Insurance allocation | E18: =D18-C18 -> 0 | F18: =IF(C18=0,0,(D18-C18)/C18) -> 0
B19: Admin / Office allocation | E19: =D19-C19 -> 0 | F19: =IF(C19=0,0,(D19-C19)/C19) -> 0
B21: PROJECT P&L SUMMARY
C22: Quoted | D22: Actual | E22: Variance $ | F22: Variance %
B23: Revenue | C23: =C4 -> 0 | D23: =D4 -> 0 | E23: =D23-C23 -> 0 | F23: =IF(C23=0,0,(D23-C23)/C23) -> 0
B24: (-) Direct Costs | C24: =C13 -> 0 | D24: =D13 -> 0 | E24: =D24-C24 -> 0 | F24: =IF(C24=0,0,(D24-C24)/C24) -> 0
B25: (-) Overhead | C25: =SUM(C17:C19) -> 0 | D25: =SUM(D17:D19) -> 0 | E25: =D25-C25 -> 0 | F25: =IF(C25=0,0,(D25-C25)/C25) -> 0
B26: NET PROFIT / LOSS | C26: =C23-C24-C25 -> 0 | D26: =D23-D24-D25 -> 0 | E26: =D26-C26 -> 0 | F26: =IF(C26=0,0,(D26-C26)/C26) -> 0
B27: NET MARGIN % | C27: =IF(C23=0,0,C26/C23) -> 0 | D27: =IF(D23=0,0,D26/D23) -> 0
B29: 📊 LABOUR RATE ANALYSIS
B30: Labour Item | C30: Estimated | D30: Actual | E30: Variance $ | F30: Notes
B31: Labour Hours (Total) | C31: =IFERROR(SUMIF('📊 Takeoff & Quote'!H11:H14,">0",'📊 Takeoff & Quote'!H11:H14)+SUMIF('📊 Takeoff & Quote'!H18:H21,">0",'📊 Takeoff & Quote'!H18:H21)+SUMIF('📊 Takeoff & Quote'!H25:H28,">0",'📊 Takeoff & Quote'!H25:H28)+SUMIF('📊 Takeoff & Quote'!H32:H37,">0",'📊 Takeoff & Quote'!H32:H37)+SUMIF('📊 Takeoff & Quote'!H41:H45,">0",'📊 Takeoff & Quote'!H41:H45)+SUMIF('📊 Takeoff & Quote'!H49:H52,">0",'📊 Takeoff & Quote'!H49:H52)+SUMIF('📊 Takeoff & Quote'!H56:H61,">0",'📊 Takeoff & Quote'!H56:H61),0) -> 0 | D31: =SUM('⏱️ Labour & Machine Log'!E3:E31) -> 0 | E31: =D31-C31 -> 0 | F31: hrs over/under estimate
B32: Our Labour Cost (@ $30/hr) | C32: =C31*'📊 Takeoff & Quote'!E8 -> 0 | D32: =IFERROR(SUMPRODUCT((ISNUMBER('⏱️ Labour & Machine Log'!G3:G31))*('⏱️ Labour & Machine Log'!G3:G31)),0) -> 0 | E32: =D32-C32 -> 0 | F32: Actual cost to Bugaboo
B33: Labour Billed to Client (@ $90/hr) | C33: =C31*'📊 Takeoff & Quote'!P8 -> 0 | D33: =IFERROR(SUMPRODUCT((ISNUMBER('⏱️ Labour & Machine Log'!L3:L31))*('⏱️ Labour & Machine Log'!L3:L31)),0) -> 0 | E33: =D33-C33 -> 0 | F33: Billed to client for labour
B34: Labour Overhead Contribution | C34: =C33-C32 -> 0 | D34: =D33-D32 -> 0 | E34: =D34-C34 -> 0 | F34: Trucks/WCB/insurance/overhead recovered
